Workbook
Name all: Feuil1!$A$1:$S$1907

Sheet Resultats arbovirus complet
A1: subjid | B1: DENV-1 | C1: DENV-2 | D1: DENV-3 | E1: DENV-4 | F1: ZIKV | G1: CHIKV | H1: RRV
A2: BO0001ILM | B2: Positive | C2: Positive | D2: Negative | E2: Positive | F2: Negative | G2: Positive | H2: Positive
A3: BO0002ILM | B3: Negative | C3: Positive | D3: Negative | E3: Negative | F3: Negative | G3: Positive | H3: Negative
A4: BO0003ILM | B4: Positive | C4: Positive | D4: Positive | E4: Positive | F4: Positive | G4: Positive | H4: Positive
A5: BO0004ILM | B5: Positive | C5: Negative | D5: Negative | E5: Positive | F5: Positive | G5: Negative | H5: Positive
A6: BO0005ILM | B6: Positive | C6: Negative | D6: Negative | E6: Negative | F6: Positive | G6: Positive | H6: Negative
A7: BO0006ILM | B7: Negative | C7: Positive | D7: Negative | E7: Negative | F7: Positive | G7: Positive | H7: Negative
A8: BO0007ILM | B8: Positive | C8: Positive | D8: Positive | E8: Positive | F8: Negative | G8: Positive | H8: Positive
A9: BO0008ILM | B9: Positive | C9: Positive | D9: Positive | E9: Positive | F9: Negative | G9: Negative | H9: Negative
A10: BO0009ILM | B10: Positive | C10: Negative | D10: Negative | E10: Positive | F10: Positive | G10: Positive | H10: Negative
A11: BO0010ILM | B11: Negative | C11: Positive | D11: Negative | E11: Negative | F11: Negative | G11: Negative | H11: Negative
A12: BO0011ILM | B12: Positive | C12: Positive | D12: Positive | E12: Positive | F12: Negative | G12: Positive | H12: Negative
... A47: BO0049ILM | B47: Positive | C47: Positive | D47: Positive | E47: Positive | F47: Negative | G47: Positive | H47: Negative
A48: BO0050ILM
A49: BO0065ILM | B49: Positive | C49: Positive | D49: Positive | E49: Positive | F49: Negative | G49: Positive | H49: Positive
A50: BO0066ILM | B50: Positive | C50: Positive | D50: Positive | E50: Positive | F50: Positive | G50: Positive | H50: Positive
A51: BO0067ILM | B51: Positive | C51: Positive | D51: Positive | E51: Positive | F51: Positive | G51: Positive | H51: Negative
A52: BO0068ILM | B52: Positive | C52: Positive | D52: Negative | E52: Positive | F52: Negative | G52: Positive | H52: Negative
A53: BO0069ILM | B53: Positive | C53: Positive | D53: Positive | E53: Positive | F53: Negative | G53: Positive | H53: Negative
A54: BO0070ILM | B54: Negative | C54: Negative | D54: Negative | E54: Negative | F54: Negative | G54: Positive | H54: Positive
A55: BO0071ILM | B55: Positive | C55: Positive | D55: Negative | E55: Positive | F55: Negative | G55: Positive | H55: Negative
A56: BO0072ILM | B56: Positive | C56: Positive | D56: Positive | E56: Positive | F56: Negative | G56: Positive | H56: Negative
A57: BO0073ILM | B57: Negative | C57: Negative | D57: Negative | E57: Negative | F57: Negative | G57: Negative | H57: Negative
A58: BO0074ILM | B58: Positive | C58: Positive | D58: Positive | E58: Positive | F58: Positive | G58: Positive | H58: Negative
A59: BO0075ILM | B59: Positive | C59: Positive | D59: Positive | E59: Positive | F59: Positive | G59: Negative | H59: Negative
A60: BO0076ILM | B60: Positive | C60: Negative | D60: Negative | E60: Negative | F60: Negative | G60: Positive | H60: Negative
... A95: BO0112ILM | B95: Positive | C95: Positive | D95: Positive | E95: Negative | F95: Negative | G95: Positive | H95: Negative
A96: BO0129ILM
A97: BO0130ILM | B97: Positive | C97: Negative | D97: Positive | E97: Positive | F97: Negative | G97: Negative | H97: Negative
A98: BO0131ILM | B98: Positive | C98: Negative | D98: Negative | E98: Negative | F98: Negative | G98: Positive | H98: Negative
A99: BO0132ILM | B99: Positive | C99: Positive | D99: Positive | E99: Positive | F99: Negative | G99: Positive | H99: Negative
A100: BO0133ILM | B100: Positive | C100: Negative | D100: Negative | E100: Positive | F100: Negative | G100: Positive | H100: Negative
A101: BO0134ILM | B101: Positive | C101: Negative | D101: Positive | E101: Positive | F101: Negative | G101: Positive | H101: Negative
A102: BO0135ILM | B102: Negative | C102: Positive | D102: Negative | E102: Negative | F102: Negative | G102: Negative | H102: Negative
A103: BO0136ILM | B103: Negative | C103: Negative | D103: Negative | E103: Negative | F103: Negative | G103: Positive | H103: Negative
A104: BO0137ILM | B104: Positive | C104: Positive | D104: Positive | E104: Positive | F104: Negative | G104: Positive | H104: Negative
A105: BO0138ILM | B105: Positive | C105: Positive | D105: Positive | E105: Negative | F105: Negative | G105: Positive | H105: Negative
A106: BO0139ILM | B106: Negative | C106: Negative | D106: Negative | E106: Negative | F106: Negative | G106: Negative | H106: Negative
A107: BO0140ILM | B107: Positive | C107: Positive | D107: Negative | E107: Positive | F107: Positive | G107: Positive | H107: Negative
A108: BO0141ILM
...

Sheet Feuil1
A1: subjid | B1: DENV1_index | C1: DENV2_index | D1: DENV3_index | E1: DENV4_index | F1: WNV_index | G1: YF_index | H1: ZIKV_index | I1: CHIKV_index | J1: RVF_index | K1: RRV_index | L1: DENV1_result | M1: DENV2_result | N1: DENV3_result | O1: DENV4_result | P1: WNV_result | Q1: YF_result | R1: ZIKV_result | S1: CHIKV_result | T1: RVF_result | U1: RRV_index | V1: annee_serologie_arbo
A2: RA0004ILM | B2: 14598 | C2: 5229.5 | D2: 13490 | E2: 17867 | F2: 57.5 | G2: 2210.5 | H2: 164.5 | I2: 17834.5 | J2: 2794 | K2: 1793.3 | L2: 1 | M2: 1 | N2: 1 | O2: 1 | P2: 0 | Q2: 0 | R2: 0 | S2: 1 | T2: 0 | U2: 1 | V2: 2020
A3: RA0001ILM | B3: 23251 | C3: 1974.5 | D3: 13769.5 | E3: 12266.5 | F3: 1803.5 | G3: 1391 | H3: 149.5 | I3: 292.5 | J3: 1737 | K3: 1186.3 | L3: 1 | M3: 1 | N3: 1 | O3: 1 | P3: 1 | Q3: 0 | R3: 0 | S3: 0 | T3: 0 | U3: 1 | V3: 2020
A4: RA0173ILM | B4: 129 | C4: -21.5 | D4: 93.5 | E4: 45.5 | F4: -71 | G4: 266 | H4: -38 | I4: 355 | J4: 175 | K4: 101.8 | L4: 0 | M4: 0 | N4: 0 | O4: 0 | P4: 0 | Q4: 0 | R4: 0 | S4: 0 | T4: 0 | U4: 0 | V4: 2020
A5: RA0010ILM | B5: 686 | C5: 332.5 | D5: 183.5 | E5: 706.5 | F5: 139.5 | G5: 57.5 | H5: -3 | I5: 91.5 | J5: 5717.5 | K5: 906.8 | L5: 0 | M5: 1 | N5: 0 | O5: 0 | P5: 0 | Q5: 0 | R5: 0 | S5: 0 | T5: 1 | U5: 0 | V5: 2020
A6: BO0192ILM | B6: 410 | C6: 38 | D6: 115.5 | E6: 1236 | F6: 396.5 | G6: 95.5 | H6: 675 | I6: 16142.5 | J6: 1823.5 | K6: 1201.8 | L6: 0 | M6: 0 | N6: 0 | O6: 0 | P6: 0 | Q6: 0 | R6: 0 | S6: 1 | T6: 0 | U6: 1 | V6: 2020
A7: BO0191ILM | B7: 19912.5 | C7: 1890 | D7: 22519.5 | E7: 14100 | F7: 142 | G7: 55.5 | H7: 93 | I7: 10837.5 | J7: 1191.5 | K7: 930.3 | L7: 1 | M7: 1 | N7: 1 | O7: 1 | P7: 0 | Q7: 0 | R7: 0 | S7: 1 | T7: 0 | U7: 0 | V7: 2020
A8: RA0008ILM | B8: 723 | C8: 812.5 | D8: 571 | E8: 1083 | F8: -23 | G8: 35 | H8: -23.5 | I8: 16083 | J8: -78 | K8: -47.2 | L8: 0 | M8: 1 | N8: 0 | O8: 0 | P8: 0 | Q8: 0 | R8: 0 | S8: 1 | T8: 0 | U8: 0 | V8: 2020
A9: BO0189ILM | B9: 18161 | C9: 1159 | D9: 8962.5 | E9: 9095 | F9: 524 | G9: 2033.5 | H9: 4121.5 | I9: 9193 | J9: 464.5 | K9: 2068.3 | L9: 1 | M9: 1 | N9: 1 | O9: 1 | P9: 0 | Q9: 0 | R9: 1 | S9: 1 | T9: 0 | U9: 1 | V9: 2020
A10: RA0018ILM | B10: 4432.5 | C10: 51.5 | D10: 1826.5 | E10: 4649.5 | F10: 59.5 | G10: 31.5 | H10: 540.5 | I10: 12799 | J10: 148 | K10: 57.8 | L10: 1 | M10: 0 | N10: 0 | O10: 1 | P10: 0 | Q10: 0 | R10: 0 | S10: 1 | T10: 0 | U10: 0 | V10: 2020
A11: RA0134ILM | B11: 945.5 | C11: -89 | D11: 534 | E11: 6004 | F11: 114.5 | G11: 140 | H11: 310.5 | I11: 18917 | J11: 170.5 | K11: 8.3 | L11: 0 | M11: 0 | N11: 0 | O11: 1 | P11: 0 | Q11: 0 | R11: 0 | S11: 1 | T11: 0 | U11: 0 | V11: 2020
A12: RA0084ILM | B12: 35 | C12: 741 | D12: 80.5 | E12: 453 | F12: 132.5 | G12: 123.5 | H12: 261 | I12: 21110.5 | J12: 416.5 | K12: 611.3 | L12: 0 | M12: 1 | N12: 0 | O12: 0 | P12: 0 | Q12: 0 | R12: 0 | S12: 1 | T12: 0 | U12: 0 | V12: 2020
A13: RA0172ILM | B13: 6997.5 | C13: 4308 | D13: 4396.5 | E13: 10077 | F13: 36.5 | G13: 5.5 | H13: 447 | I13: 37840.5 | J13: -31.5 | K13: 1235.3 | L13: 1 | M13: 1 | N13: 1 | O13: 1 | P13: 0 | Q13: 0 | R13: 0 | S13: 1 | T13: 0 | U13: 1 | V13: 2020
... A1907: TA8792ILM | B1907: 3609 | C1907: -164.5 | D1907: 911 | E1907: 0 | F1907: -166 | G1907: -139.5 | H1907: -453.5 | I1907: 6112.5 | J1907: -101 | K1907: 304 | L1907: 1 | M1907: 0 | N1907: 0 | O1907: 0 | P1907: 0 | Q1907: 0 | R1907: 0 | S1907: 1 | T1907: 0 | U1907: 0 | V1907: 2022
L1909: =SUM(L2:L1907) -> 1447 | M1909: =SUM(M2:M1907) -> 848 | N1909: =SUM(N2:N1907) -> 957 | O1909: =SUM(O2:O1907) -> 840 | P1909: =SUM(P2:P1907) -> 97 | Q1909: =SUM(Q2:Q1907) -> 46 | R1909: =SUM(R2:R1907) -> 668 | S1909: =SUM(S2:S1907) -> 1299 | ... U1909: =SUM(U2:U1907) -> 393

Sheet Feuil2
B1: +-----------+
B2: | | C2: subjid | D2: |
B3: |-----------|
B4: 47. | C4: | | D4: BO0050ILM | E4: =COUNTIF(Feuil1!A:A,Feuil2!D4) -> 0
B5: 95. | C5: | | D5: BO0129ILM | E5: =COUNTIF(Feuil1!A:A,Feuil2!D5) -> 0
B6: 107. | C6: | | D6: BO0141ILM | E6: =COUNTIF(Feuil1!A:A,Feuil2!D6) -> 0
B7: 185. | C7: | | D7: FA0201ILM | E7: =COUNTIF(Feuil1!A:A,Feuil2!D7) -> 0
B8: 225. | C8: | | D8: GA0208ILM | E8: =COUNTIF(Feuil1!A:A,Feuil2!D8) -> 0
B9: |-----------| | E9: =COUNTIF(Feuil1!A:A,Feuil2!D9) -> 0
B10: 228. | C10: | | D10: GA0211ILM | E10: =COUNTIF(Feuil1!A:A,Feuil2!D10) -> 0
B11: 239. | C11: | | D11: GA0226ILM | E11: =COUNTIF(Feuil1!A:A,Feuil2!D11) -> 0
B12: 242. | C12: | | D12: GA0229ILM | E12: =COUNTIF(Feuil1!A:A,Feuil2!D12) -> 0
B13: 254. | C13: | | D13: GA0246ILM | E13: =COUNTIF(Feuil1!A:A,Feuil2!D13) -> 0
B14: 259. | C14: | | D14: GA0251ILM | E14: =COUNTIF(Feuil1!A:A,Feuil2!D14) -> 0
B15: |-----------| | E15: =COUNTIF(Feuil1!A:A,Feuil2!D15) -> 0
B16: 276. | C16: | | D16: HA0231ILM | E16: =COUNTIF(Feuil1!A:A,Feuil2!D16) -> 0
B17: 331. | C17: | | D17: HI0249ILM | E17: =COUNTIF(Feuil1!A:A,Feuil2!D17) -> 0
B18: 451. | C18: | | D18: MO0104ILM | E18: =COUNTIF(Feuil1!A:A,Feuil2!D18) -> 0
B19: 455. | C19: | | D19: MO0108ILM | E19: =COUNTIF(Feuil1!A:A,Feuil2!D19) -> 0
B20: 463. | C20: | | D20: MO0116ILM | E20: =COUNTIF(Feuil1!A:A,Feuil2!D20) -> 0
B21: |-----------| | E21: =COUNTIF(Feuil1!A:A,Feuil2!D21) -> 0
B22: 480. | C22: | | D22: MO0135ILM | E22: =COUNTIF(Feuil1!A:A,Feuil2!D22) -> 0
B23: 508. | C23: | | D23: NU0209ILM | E23: =COUNTIF(Feuil1!A:A,Feuil2!D23) -> 0
B24: 537. | C24: | | D24: NU0241ILM | E24: =COUNTIF(Feuil1!A:A,Feuil2!D24) -> 0
B25: 543. | C25: | | D25: NU0247ILM | E25: =COUNTIF(Feuil1!A:A,Feuil2!D25) -> 0
B26: 580. | C26: | | D26: NU0289ILM | E26: =COUNTIF(Feuil1!A:A,Feuil2!D26) -> 0
B27: |-----------| | E27: =COUNTIF(Feuil1!A:A,Feuil2!D27) -> 0
B28: 860. | C28: | | D28: RG0064ILM | E28: =COUNTIF(Feuil1!A:A,Feuil2!D28) -> 0
B29: 879. | C29: | | D29: RG0084ILM | E29: =COUNTIF(Feuil1!A:A,Feuil2!D29) -> 0
B30: 880. | C30: | | D30: RG0085ILM | E30: =COUNTIF(Feuil1!A:A,Feuil2!D30) -> 0
B31: 912. | C31: | | D31: RI0207ILM | E31: =COUNTIF(Feuil1!A:A,Feuil2!D31) -> 0
B32: 937. | C32: | | D32: RU0013ILM | E32: =COUNTIF(Feuil1!A:A,Feuil2!D32) -> 0
B33: |-----------| | E33: =COUNTIF(Feuil1!A:A,Feuil2!D33) -> 0
A34: 1067. | B34: | | D34: TA8029ILM | E34: =COUNTIF(Feuil1!A:A,Feuil2!D34) -> 0
A35: 1104. | B35: | | D35: TA8207ILM | E35: =COUNTIF(Feuil1!A:A,Feuil2!D35) -> 0
A36: 1180. | B36: | | D36: TA8320ILM | E36: =COUNTIF(Feuil1!A:A,Feuil2!D36) -> 0
A37: 1221. | B37: | | D37: TA8362ILM | E37: =COUNTIF(Feuil1!A:A,Feuil2!D37) -> 0
A38: 1506. | B38: | | D38: TA8668ILM | E38: =COUNTIF(Feuil1!A:A,Feuil2!D38) -> 0
B39: |-----------| | E39: =COUNTIF(Feuil1!A:A,Feuil2!D39) -> 0
A40: 1578. | B40: | | D40: TA8749ILM | E40: =COUNTIF(Feuil1!A:A,Feuil2!D40) -> 0
...
